# 자원 정리

- 기존에 작성했던 코드는 여러 클라이언트와 연결할 수 있었다.
- 하지만, 중간에 강제 종료하는 경우 자원이 적절하게 정리되지 못하는 문제가 발생한다.
- 모든 상황에서 적절하게 자원정리를 하려면 어떻게 해야할까?

## 안 좋은 예

```java
public static void main(String[] args) {
	try {
		logic();
	} catch (CallException e) {
		System.out.println("CallException 예외 처리");
		throw new RuntimeException(e);
	} catch (CloseException e) {
		System.out.println("CloseException 예외 처리");
		throw new RuntimeException(e);
	}
}
	
private static void logic() throws CallException, CloseException {
	ResourceV1 resource1 = new ResourceV1("resource1");
	ResourceV1 resource2 = new ResourceV1("resource2");
	
	resource1.call();
	resource2.callEx(); // 예외 발생, 자원 정리 호출 X
	
	System.out.println("자원 정리");
	resource2.closeEx();
	resource1.close();
}
```

- 이렇게 코드를 작성하게 되면, 자원 정리가 되지 않는다.
- 예외가 발생하더라도 자원 정리를 할 수 있도록 코드를 작성해야 한다.

## 예외가 발생하더라도 자원 정리

```java
private static void logic() throws CloseException {
	ResourceV1 resource1 = new ResourceV1("resource1");
	ResourceV1 resource2 = new ResourceV1("resource2");
	
	try {
		resource1.call();
		resource2.callEx(); // 예외 발생, 자원 정리 호출 X
	} catch (CallException e) {
		throw new RuntimeException(e);
	} finally {
		System.out.println("자원 정리");
		resource2.closeEx();
		resource1.close();
	}
}
```

- 이제 `callEx()`에서 예외가 발생하더라도 자원 정리가 된다.
- 하지만 문제는 자원 정리에서 또 예외가 발생하는 경우에는 다른 자원을 정리하지 못하는 등, 처리를 제대로 하지 못한다. (**자원 정리 중 예외**)
- 또한 객체를 외부에서 생성하는데, 객체를 생성하는 과정에서도 예외가 발생할 수 있다.
  - 이 경우, 메서드를 호출하는 과정에서 NPE가 발생하거나... 복잡하다.
- 또한 `CallException` 때문에 finally가 호출되다가, 또 `CloseException`이 발생하면 외부에는 `CloseException`만 호출된다. (**핵심 예외 변경**)

## 자원 정리 중 예외가 발생하더라도 자원 정리

```java
public static void main(String[] args) {
	try {
		logic();
	} catch (CallException e) {
		System.out.println("Call Exception 예외 처리");
		throw new RuntimeException(e);
	}
}
	
private static void logic() throws CallException {
	ResourceV1 resource1 = null;
	ResourceV1 resource2 = null;
	
	try {
		resource1 = new ResourceV1("resource1");
		resource2 = new ResourceV1("resource2");
		resource1.call();
		resource2.callEx(); // 예외 발생, 자원 정리 호출 X
	} catch (CallException e) {
		System.out.println("ex: " + e);
		throw e;
	} finally {
		System.out.println("자원 정리");
		if (resource2 != null) {
			try {
				resource2.closeEx();
			} catch (CloseException e) {
				System.out.println("close ex: " + e);
			}
		}
		if (resource1 != null) {
			try {
				resource1.close();
			} catch (CloseException e) {
				System.out.println("close ex: " + e);
			}
		}
	}
}
```

- 모든 문제를 해결했지만 아쉬운 부분이 몇가지 있다.
- 리소스를 생성하며 바로 할당할 수 없다.
  - `finally` 블록에서는 `try` 블록의 지역변수에 접근할 수 없다.
  - 이 때문에 해당 객체의 `scope`가 덩달아 커진다.
- 코드가 복잡하다.
  - 유지보수성이 똥이다.
  - 개발자가 `close()`를 빼먹거나, 순서를 잘못 적을 수 있다.
- `try-with-resources` 로 해결해보자.

## try-with-resources

```java
public static void main(String[] args) {
	try {
		logic();
	} catch (CallException e) {
		System.out.println("Call Exception 예외 처리");
		throw new RuntimeException(e);
	} catch (CloseException e) {
		System.out.println("Close Exception 예외 처리");
		throw new RuntimeException(e);
	}
}
	
private static void logic() throws CallException, CloseException {
	try (
			ResourceV2 resource1 = new ResourceV2("resource1");
			ResourceV2 resource2 = new ResourceV2("resource2")
	) {
		resource1.call();
		resource2.callEx();
	} catch (CallException e) {
		System.out.println("ex: " + e);
		throw e;
	}
}
```

- `try-with-resources`는 선언한 순서의 반대로 닫아준다.
- 코드가 매우 간결해진다.
- 또한 한 리소스의 `close()` 메서드 호출 중 예외가 터지면, 해당 예외가 핵심 예외가 아니라고 판단하고, `Suppressed`한다.
  - 만약 핵심 예외가 터지면, 핵심 예외 안에 해당 `close()` 예외를 넣어준다.
  - 만약 핵심 예외가 터지지 않았다면, 정상적으로 `close()` 예외를 터트린다.
  - 즉, 부가 예외는 핵심 예외에 포함하여 터트려준다.
- 스코프의 범위도 `try-catch-resources` 내부로 한정 지을 수 있다.
